Workbook

Sheet Cost_Sheet
A1: Saryarqa Go — Cost and Payback Sheet (KZT)
A2: All numbers are formulas linked to the Inputs, Budget_8M, Cashflow and Summary sheets. Planning assumptions, not a forecast.
A4: 1. One-time costs
A5: =Budget_8M!B5 -> Senior full-stack developer (contract) | B5: =Budget_8M!D5 -> 2100000
A6: =Budget_8M!B6 -> UX/UI design finishing (freelance) | B6: =Budget_8M!D6 -> 400000
A7: =Budget_8M!B7 -> Localization ZH + EN, native proofreading | B7: =Budget_8M!D7 -> 600000
A8: =Budget_8M!B8 -> Legal: offer, refund rules, privacy, PD consent | B8: =Budget_8M!D8 -> 450000
A9: =Budget_8M!B9 -> Payment provider onboarding + real test payments | B9: =Budget_8M!D9 -> 150000
A10: =Budget_8M!B10 -> Guide videos + tour photos (4 guides, 4 tours) | B10: =Budget_8M!D10 -> 500000
A11: =Budget_8M!B11 -> Pre-launch security review | B11: =Budget_8M!D11 -> 250000
A12: =Budget_8M!B12 -> Interviews + usability tests (incentives, recruiting) | B12: =Budget_8M!D12 -> 250000
A13: =Budget_8M!B14 -> Printed postcards + QR cards | B13: =Budget_8M!D14 -> 100000
A14: One-time total | B14: =SUM(B5:B13) -> 4800000
A16: 2. Monthly operating costs
A17: Item | B17: KZT / month | C17: Months
A18: =Budget_8M!B13 -> Xiaohongshu content + KOC collaborations | B18: =Budget_8M!D13/(Budget_8M!F13-Budget_8M!E13+1) -> 133333.33 | C18: ="M"&Budget_8M!E13&"–"&Budget_8M!F13 -> M4–12
A19: =Budget_8M!B15 -> Hosting, CDN, database, domain, e-mail, monitoring | B19: =Budget_8M!D15/(Budget_8M!F15-Budget_8M!E15+1) -> 25000 | C19: ="M"&Budget_8M!E15&"–"&Budget_8M!F15 -> M1–12
A20: =Budget_8M!B16 -> Chinese-speaking support, part-time | B20: =Budget_8M!D16/(Budget_8M!F16-Budget_8M!E16+1) -> 120000 | C20: ="M"&Budget_8M!E16&"–"&Budget_8M!F16 -> M4–12
A21: =Budget_8M!B17 -> Contingency reserve (assumed fully used) | B21: =Budget_8M!D17/(Budget_8M!F17-Budget_8M!E17+1) -> 62000 | C21: ="M"&Budget_8M!E17&"–"&Budget_8M!F17 -> M3–12
A22: Operating cost by month, year 1 | C22: =Budget_8M!C39+Budget_8M!C41+Budget_8M!C42+Budget_8M!C43 -> 25000 | D22: =Budget_8M!D39+Budget_8M!D41+Budget_8M!D42+Budget_8M!D43 -> 25000 | E22: =Budget_8M!E39+Budget_8M!E41+Budget_8M!E42+Budget_8M!E43 -> 87000 | F22: =Budget_8M!F39+Budget_8M!F41+Budget_8M!F42+Budget_8M!F43 -> 340333.33 | G22: =Budget_8M!G39+Budget_8M!G41+Budget_8M!G42+Budget_8M!G43 -> 340333.33 | H22: =Budget_8M!H39+Budget_8M!H41+Budget_8M!H42+Budget_8M!H43 -> 340333.33 | I22: =Budget_8M!I39+Budget_8M!I41+Budget_8M!I42+Budget_8M!I43 -> 340333.33 | J22: =Budget_8M!J39+Budget_8M!J41+Budget_8M!J42+Budget_8M!J43 -> 340333.33 | ... N22: =Budget_8M!N39+Budget_8M!N41+Budget_8M!N42+Budget_8M!N43 -> 340333.33
A23: (columns C–N = months 1–12)
A24: Operating cost per month from month 13 (hosting, support, developer retainer, marketing) | B24: =Inputs!B24 -> 395000
A26: 3. Total first-year costs
A27: One-time costs | B27: =B14 -> 4800000
A28: 12 months of operating costs | B28: =SUM(C22:N22) -> 3200000
A29: Total first-year costs (one-time + 12 months operating) | B29: =B27+B28 -> 8000000
A30: Case budget limit (Technology Product) | B30: 20000000
A31: Check | B31: =IF(B29<=B30,"within limit","OVER LIMIT") -> within limit
A32: Check: equals the Phase 1 budget sheet | B32: =IF(B29=Budget_8M!D18,"OK","CHECK") -> OK
A34: 4. Revenue assumptions
A35: Average tour price per traveler (case fact) | B35: =Inputs!B4 -> 44000
A36: Contribution margin (team assumption, to confirm) | B36: =Inputs!B5 -> 0.3
A37: Contribution per extra foreign traveler | B37: =Inputs!B17 -> 13200
A38: Extra foreign travelers per year at the company target | B38: =Inputs!B22 -> 1262.8571
A39: Launch month (first bookings) | B39: =Inputs!B9 -> 4
A40: Travelers per month to cover month-13 costs | B40: =Inputs!B25 -> 29.924242
A42: 5. Payback and worst case (30% lower results)
B43: =Summary!B3 -> Company target (100%) | C43: =Summary!C3 -> Worst case −30% (required) | D43: =Summary!D3 -> Stress test
A44: Payback month (cumulative cash ≥ 0) | B44: =Summary!B15 -> 22 | C44: =Summary!C15 -> 28 | D44: =Summary!D15 -> not within 60
A45: Lowest cumulative cash flow | B45: =Summary!B12 -> -5646421.8 | C45: =Summary!C12 -> -6022800 | D45: =Summary!D12 -> -8576367.3
...

Sheet Summary
A1: Summary — slide 7 and the Impact page
A3: Metric | B3: Company target (100%) | C3: Worst case −30% (required) | D3: Stress test
A4: Contribution margin | B4: =Inputs!C29 -> 0.3 | C4: =Inputs!C30 -> 0.3 | D4: =Inputs!C31 -> 0.25
A5: Volume (% of company target) | B5: =Inputs!B29 -> 1 | C5: =Inputs!B30 -> 0.7 | D5: =Inputs!B31 -> 0.4
A6: Launch month | B6: =Inputs!$B$9+Inputs!D29 -> 4 | C6: =Inputs!$B$9+Inputs!D30 -> 4 | D6: =Inputs!$B$9+Inputs!D31 -> 6
A7: Travelers in year 1 (months 1–12) | B7: =SUM(Cashflow!C5:C16) -> 225.5102 | C7: =SUM(Cashflow!I5:I16) -> 157.85714 | D7: =SUM(Cashflow!O5:O16) -> 56.126984
A8: Travelers in year 2 (months 13–24) | B8: =SUM(Cashflow!C17:C28) -> 932.10884 | C8: =SUM(Cashflow!I17:I28) -> 652.47619 | D8: =SUM(Cashflow!O17:O28) -> 324.73469
A9: Travelers in year 3 (months 25–36) | B9: =SUM(Cashflow!C29:C40) -> 1262.8571 | C9: =SUM(Cashflow!I29:I40) -> 884 | D9: =SUM(Cashflow!O29:O40) -> 503.13832
A10: Gross bookings, months 1–48 (revenue, NOT profit) | B10: =SUM(Cashflow!D5:D52) -> 1.6206667e+08 | C10: =SUM(Cashflow!J5:J52) -> 1.1344667e+08 | D10: =SUM(Cashflow!P5:P52) -> 61122286
A11: Contribution, months 1–48 | B11: =SUM(Cashflow!E5:E52) -> 48620000 | C11: =SUM(Cashflow!K5:K52) -> 34034000 | D11: =SUM(Cashflow!Q5:Q52) -> 15280571
A12: Lowest cumulative cash flow | B12: =MIN(Cashflow!$G$5:$G$64) -> -5646421.8 | C12: =MIN(Cashflow!$M$5:$M$64) -> -6022800 | D12: =MIN(Cashflow!$S$5:$S$64) -> -8576367.3
A13: Month of lowest point | B13: =MATCH(MIN(Cashflow!$G$5:$G$64),Cashflow!$G$5:$G$64,0) -> 8 | C13: =MATCH(MIN(Cashflow!$M$5:$M$64),Cashflow!$M$5:$M$64,0) -> 10 | D13: =MATCH(MIN(Cashflow!$S$5:$S$64),Cashflow!$S$5:$S$64,0) -> 22
A14: Monthly break-even month (first month with cash flow ≥ 0) | B14: =IFERROR(MATCH(1,Cashflow!$H$5:$H$64,0),"not within 60") -> 9 | C14: =IFERROR(MATCH(1,Cashflow!$N$5:$N$64,0),"not within 60") -> 11 | D14: =IFERROR(MATCH(1,Cashflow!$T$5:$T$64,0),"not within 60") -> 23
A15: Payback month (cumulative ≥ 0) | B15: =IF(COUNTIF(Cashflow!$G$5:$G$64,"<0")>=60,"not within 60",COUNTIF(Cashflow!$G$5:$G$64,"<0")+1) -> 22 | C15: =IF(COUNTIF(Cashflow!$M$5:$M$64,"<0")>=60,"not within 60",COUNTIF(Cashflow!$M$5:$M$64,"<0")+1) -> 28 | D15: =IF(COUNTIF(Cashflow!$S$5:$S$64,"<0")>=60,"not within 60",COUNTIF(Cashflow!$S$5:$S$64,"<0")+1) -> not within 60
A16: Cumulative cash flow at month 48 | B16: =Cashflow!G52 -> 26400000 | C16: =Cashflow!M52 -> 11814000 | D16: =Cashflow!S52 -> -6939428.6
A17: Marketing spend per traveler, year 1 (KZT) | B17: =IFERROR((Budget_8M!D13+Budget_8M!D14)/B7,"-") -> 5764.7059 | C17: =IFERROR((Budget_8M!D13+Budget_8M!D14)/C7,"-") -> 8235.2941 | D17: =IFERROR((Budget_8M!D13+Budget_8M!D14)/D7,"-") -> 23161.765
A18: Marketing spend per traveler, year 2 (KZT) | B18: =IFERROR(Inputs!$B$14*12/B8,"-") -> 1931.1049 | C18: =IFERROR(Inputs!$B$14*12/C8,"-") -> 2758.7214 | D18: =IFERROR(Inputs!$B$14*12/D8,"-") -> 5542.9864
A20: Marketing per traveler year 1 uses budget lines 9–10 (Xiaohongshu + postcards). It is the acquisition cost the slide shows; it is not hidden in the margin.
A21: Payback month uses COUNTIF of negative cumulative months + 1. Valid because cumulative cash flow falls first, then rises and stays positive in every scenario here.

Sheet README
A1: Saryarqa Go — Cost and Payback Sheet: Phase 1 budget 8,000,000 KZT within the 20,000,000 KZT case cap
A2: ZERTTEX Hackathon 2026, Final (Stage 2), Case 1 Technology Product. Updated 27 Oct 2026. All amounts in KZT.
A3: Case cap 20,000,000 KZT (organizers). We ask for 8,000,000 now (Phase 1); up to 12,000,000 more (Phase 2) only after the month-9 stage gate.
A4: How to read this workbook
A5: Blue text = inputs you can change. Black = formulas. Green = links to another sheet. Yellow fill = key assumptions that must be confirmed with Saryarqa Routes.
A6: Change any blue cell on "Inputs" or "Budget_8M" and every sheet recalculates.
A8: Sheets
A9: Inputs — price, margin, target, launch month, running costs after year 1, three scenarios.
A10: Budget_8M — the 13 Phase 1 lines that add up to exactly 8,000,000 KZT, with timing and a reason for each line; what is done unpaid; what is in Phase 2.
A11: Cashflow — month-by-month travelers, gross bookings, contribution, costs, cash flow and cumulative cash flow for three scenarios (60 months).
A12: Summary (first sheet) — the numbers on slide 7 and on the prototype's Impact page: lowest point, monthly break-even, payback month, totals by year.
A13: Sensitivity — payback month for margin 20–35% × volume 40–100% of the company target.
... A30: Nothing in this model is a forecast of guaranteed results. Scenarios are tools for decisions (see the month-9 stage gate on slide 8).

Sheet Inputs
A1: Inputs
A3: Input | B3: Value | C3: Source / note
A4: Average tour price per traveler (KZT) | B4: 44000 | C4: Case data (ZERTTEX case "Saryarqa Routes"), as used in our PDF.
A5: Contribution margin after guides, transport, hotels, payment fees | B5: 0.3 | C5: Our PDF assumption. NOT confirmed by the company. Check in week 1.
A6: Travelers today (all) | B6: 3400 | C6: Case data.
A7: Share of foreign travelers today | B7: 0.04 | C7: Case data (≈96% from Kazakhstan).
A8: Target share of foreign travelers in 24 months | B8: 0.3 | C8: Case data (company goal).
A9: Launch month (first bookings) | B9: 4 | C9: After a 12-week MVP build (weeks 1–12).
A10: Month in which the target run-rate is reached | B10: 24 | C10: Company goal: 30% foreign within 24 months.
A11: Running costs after month 12: hosting & tools (KZT/month) | B11: 25000 | C11: Our estimate: hosting/CDN reachable from China, DB, e-mail, monitoring.
A12: Running costs after month 12: Chinese-speaking support (KZT/month) | B12: 120000 | C12: Our estimate: part-time support, about 20 h/week.
A13: Running costs after month 12: developer retainer for fixes (KZT/month) | B13: 100000 | C13: Our estimate: about 1 week of developer time per month.
A14: Marketing after month 12 (KZT/month) | B14: 150000 | C14: Our estimate: own Xiaohongshu posts + small KOC collaborations. Acquisition cost is NOT hidden.
A16: Derived (formulas)
A17: Contribution per additional foreign traveler (KZT) | B17: =B4*B5 -> 13200
A18: Local travelers today | B18: =B6*(1-B7) -> 3264
A19: Foreign travelers today | B19: =B6*B7 -> 136
A20: Total travelers needed if locals stay the same | B20: =B18/(1-B8) -> 4662.8571
A21: Foreign travelers needed per year | B21: =B20*B8 -> 1398.8571
A22: Additional foreign travelers per year (target) | B22: =B21-B19 -> 1262.8571
A23: Target run-rate per month | B23: =B22/12 -> 105.2381
A24: Running costs + marketing after month 12 (KZT/month) | B24: =SUM(B11:B14) -> 395000
A25: Travelers per month needed to cover running costs + marketing | B25: =B24/B17 -> 29.924242
A27: Scenarios
A28: Scenario | B28: Volume (% of company target path) | C28: Contribution margin | D28: Launch delay (months) | E28: Why
A29: Company target (100%) | B29: 1 | C29: 0.3 | D29: 0 | E29: The company goal (30% foreign within 24 months) reached on time.
A30: Worst case −30% (required) | B30: 0.7 | C30: 0.3 | D30: 0 | E30: Required by the rules: 30% lower results than the target path. Also our realistic plan, since Phase 1 has only 1.2M for marketing.
A31: Stress test | B31: 0.4 | C31: 0.25 | D31: 2 | E31: Extra test: 40% of target, margin 25%, payment approval delays launch by 2 months. Triggers the month-9 stage gate.

Sheet Budget_8M
A1: Phase 1 budget: 8,000,000 KZT (12 months), within the 20,000,000 KZT case cap
A2: Built bottom-up from the MVP scope, not by cutting the 20M plan proportionally. Blue = editable. Monthly spread is used by the Cashflow sheet.
A4: # | B4: Budget line | C4: Group | D4: KZT | E4: Start month | F4: End month | G4: Why it is needed / how the amount was set
A5: 1 | B5: Senior full-stack developer (contract) | C5: Build | D5: 2100000 | E5: 1 | F5: 3 | G5: Booking flow, payment-page integration, admin page, database, security basics. 3 months × 700,000. Benchmark: hh.kz median salary expectation for senior IT specialists ≈508,000 KZT/month (Q1 2026) + contract premium.
A6: 2 | B6: UX/UI design finishing (freelance) | C6: Build | D6: 400000 | E6: 1 | F6: 2 | G6: Turn the prototype into a consistent, accessible design system for EN/ZH (mobile first). About 4 weeks part-time.
A7: 3 | B7: Localization ZH + EN, native proofreading | C7: Build | D7: 600000 | E7: 2 | F7: 3 | G7: UI, 4 tour pages × 4 lists, trust page, refund rules, privacy notice, chat scripts. Translation + native Chinese proofreading.
A8: 4 | B8: Legal: offer, refund rules, privacy, PD consent | C8: Build | D8: 450000 | E8: 1 | F8: 3 | G8: Public offer / terms, refund rules, privacy notice and personal-data consent under Kazakhstan law, review of the payment-provider contract.
A9: 5 | B9: Payment provider onboarding + real test payments | C9: Build | D9: 150000 | E9: 2 | F9: 3 | G9: Provider set-up fees (if any) and real test payments with foreign cards before launch.
A10: 6 | B10: Guide videos + tour photos (4 guides, 4 tours) | C10: Build | D10: 500000 | E10: 2 | F10: 3 | G10: 60–90 s video per guide with ZH/EN subtitles + photos of 4 tours. Hosted on our own storage (YouTube is not reachable from mainland China).
A11: 7 | B11: Pre-launch security review | C11: Build | D11: 250000 | E11: 3 | F11: 3 | G11: External review of payment flow, admin access and data storage before real payments start.
A12: 8 | B12: Interviews + usability tests (incentives, recruiting) | C12: Validation | D12: 250000 | E12: 1 | F12: 3 | G12: At least 10 interviews + 5–8 usability sessions with Chinese-speaking travelers: small incentives, recruiting posts.
A13: 9 | B13: Xiaohongshu content + KOC collaborations | C13: Launch | D13: 1200000 | E13: 4 | F13: 12 | G13: Our own Xiaohongshu notes + short videos, small paid collaborations with travel creators (KOC). Months 4–12.
A14: 10 | B14: Printed postcards + QR cards | C14: Launch | D14: 100000 | E14: 4 | F14: 4 | G14: Postcards with QR code for guides, hotels and hostels partners (pilot quantity).
A15: 11 | B15: Hosting, CDN, database, domain, e-mail, monitoring | C15: Operations Y1 | D15: 300000 | E15: 1 | F15: 12 | G15: Hosting and CDN reachable from mainland China, database, domain, e-mail, monitoring. ≈25,000/month.
A16: 12 | B16: Chinese-speaking support, part-time | C16: Operations Y1 | D16: 1080000 | E16: 4 | F16: 12 | G16: Part-time Chinese-speaking support: chat hand-off and 5-minute WeChat video calls before payment. 9 months × 120,000.
A17: 13 | B17: Contingency reserve (assumed fully used) | C17: Reserve | D17: 620000 | E17: 3 | F17: 12 | G17: About 8% of the budget for overruns and post-launch fixes. Assumed fully spent in the model.
B18: TOTAL | D18: =SUM(D5:D17) -> 8000000
B19: Check: total equals 8,000,000 | D19: =IF(D18=8000000,"OK","NOT 8M") -> OK
B20: Room left under the 20,000,000 KZT case cap (Phase 2, only after the month-9 stage gate) | D20: =20000000-D18 -> 12000000
B21: Subtotals by group
B22: Build | D22: =SUMIF($C$5:$C$17,B22,$D$5:$D$17) -> 4450000 | E22: =D22/$D$18 -> 0.55625
B23: Validation | D23: =SUMIF($C$5:$C$17,B23,$D$5:$D$17) -> 250000 | E23: =D23/$D$18 -> 0.03125
B24: Launch | D24: =SUMIF($C$5:$C$17,B24,$D$5:$D$17) -> 1300000 | E24: =D24/$D$18 -> 0.1625
B25: Operations Y1 | D25: =SUMIF($C$5:$C$17,B25,$D$5:$D$17) -> 1380000 | E25: =D25/$D$18 -> 0.1725
B26: Reserve | D26: =SUMIF($C$5:$C$17,B26,$D$5:$D$17) -> 620000 | E26: =D26/$D$18 -> 0.0775
A29: Monthly spend (formula: amount ÷ number of months, inside start–end)
A30: # | B30: Budget line | C30: M1 | D30: M2 | E30: M3 | F30: M4 | G30: M5 | H30: M6 | I30: M7 | J30: M8 | K30: M9 | L30: M10 | M30: M11 | N30: M12
A31: 1 | B31: =B5 -> Senior full-stack developer (contract) | C31: =IF(AND(1>=$E$5,1<=$F$5),$D$5/($F$5-$E$5+1),0) -> 700000 | D31: =IF(AND(2>=$E$5,2<=$F$5),$D$5/($F$5-$E$5+1),0) -> 700000 | E31: =IF(AND(3>=$E$5,3<=$F$5),$D$5/($F$5-$E$5+1),0) -> 700000 | F31: =IF(AND(4>=$E$5,4<=$F$5),$D$5/($F$5-$E$5+1),0) -> 0 | G31: =IF(AND(5>=$E$5,5<=$F$5),$D$5/($F$5-$E$5+1),0) -> 0 | H31: =IF(AND(6>=$E$5,6<=$F$5),$D$5/($F$5-$E$5+1),0) -> 0 | I31: =IF(AND(7>=$E$5,7<=$F$5),$D$5/($F$5-$E$5+1),0) -> 0 | J31: =IF(AND(8>=$E$5,8<=$F$5),$D$5/($F$5-$E$5+1),0) -> 0 | K31: =IF(AND(9>=$E$5,9<=$F$5),$D$5/($F$5-$E$5+1),0) -> 0 | L31: =IF(AND(10>=$E$5,10<=$F$5),$D$5/($F$5-$E$5+1),0) -> 0 | M31: =IF(AND(11>=$E$5,11<=$F$5),$D$5/($F$5-$E$5+1),0) -> 0 | N31: =IF(AND(12>=$E$5,12<=$F$5),$D$5/($F$5-$E$5+1),0) -> 0
A32: 2 | B32: =B6 -> UX/UI design finishing (freelance) | C32: =IF(AND(1>=$E$6,1<=$F$6),$D$6/($F$6-$E$6+1),0) -> 200000 | D32: =IF(AND(2>=$E$6,2<=$F$6),$D$6/($F$6-$E$6+1),0) -> 200000 | E32: =IF(AND(3>=$E$6,3<=$F$6),$D$6/($F$6-$E$6+1),0) -> 0 | F32: =IF(AND(4>=$E$6,4<=$F$6),$D$6/($F$6-$E$6+1),0) -> 0 | G32: =IF(AND(5>=$E$6,5<=$F$6),$D$6/($F$6-$E$6+1),0) -> 0 | H32: =IF(AND(6>=$E$6,6<=$F$6),$D$6/($F$6-$E$6+1),0) -> 0 | I32: =IF(AND(7>=$E$6,7<=$F$6),$D$6/($F$6-$E$6+1),0) -> 0 | J32: =IF(AND(8>=$E$6,8<=$F$6),$D$6/($F$6-$E$6+1),0) -> 0 | K32: =IF(AND(9>=$E$6,9<=$F$6),$D$6/($F$6-$E$6+1),0) -> 0 | L32: =IF(AND(10>=$E$6,10<=$F$6),$D$6/($F$6-$E$6+1),0) -> 0 | M32: =IF(AND(11>=$E$6,11<=$F$6),$D$6/($F$6-$E$6+1),0) -> 0 | N32: =IF(AND(12>=$E$6,12<=$F$6),$D$6/($F$6-$E$6+1),0) -> 0
A33: 3 | B33: =B7 -> Localization ZH + EN, native proofreading | C33: =IF(AND(1>=$E$7,1<=$F$7),$D$7/($F$7-$E$7+1),0) -> 0 | D33: =IF(AND(2>=$E$7,2<=$F$7),$D$7/($F$7-$E$7+1),0) -> 300000 | E33: =IF(AND(3>=$E$7,3<=$F$7),$D$7/($F$7-$E$7+1),0) -> 300000 | F33: =IF(AND(4>=$E$7,4<=$F$7),$D$7/($F$7-$E$7+1),0) -> 0 | G33: =IF(AND(5>=$E$7,5<=$F$7),$D$7/($F$7-$E$7+1),0) -> 0 | H33: =IF(AND(6>=$E$7,6<=$F$7),$D$7/($F$7-$E$7+1),0) -> 0 | I33: =IF(AND(7>=$E$7,7<=$F$7),$D$7/($F$7-$E$7+1),0) -> 0 | J33: =IF(AND(8>=$E$7,8<=$F$7),$D$7/($F$7-$E$7+1),0) -> 0 | K33: =IF(AND(9>=$E$7,9<=$F$7),$D$7/($F$7-$E$7+1),0) -> 0 | L33: =IF(AND(10>=$E$7,10<=$F$7),$D$7/($F$7-$E$7+1),0) -> 0 | M33: =IF(AND(11>=$E$7,11<=$F$7),$D$7/($F$7-$E$7+1),0) -> 0 | N33: =IF(AND(12>=$E$7,12<=$F$7),$D$7/($F$7-$E$7+1),0) -> 0
A34: 4 | B34: =B8 -> Legal: offer, refund rules, privacy, PD consent | C34: =IF(AND(1>=$E$8,1<=$F$8),$D$8/($F$8-$E$8+1),0) -> 150000 | D34: =IF(AND(2>=$E$8,2<=$F$8),$D$8/($F$8-$E$8+1),0) -> 150000 | E34: =IF(AND(3>=$E$8,3<=$F$8),$D$8/($F$8-$E$8+1),0) -> 150000 | F34: =IF(AND(4>=$E$8,4<=$F$8),$D$8/($F$8-$E$8+1),0) -> 0 | G34: =IF(AND(5>=$E$8,5<=$F$8),$D$8/($F$8-$E$8+1),0) -> 0 | H34: =IF(AND(6>=$E$8,6<=$F$8),$D$8/($F$8-$E$8+1),0) -> 0 | I34: =IF(AND(7>=$E$8,7<=$F$8),$D$8/($F$8-$E$8+1),0) -> 0 | J34: =IF(AND(8>=$E$8,8<=$F$8),$D$8/($F$8-$E$8+1),0) -> 0 | K34: =IF(AND(9>=$E$8,9<=$F$8),$D$8/($F$8-$E$8+1),0) -> 0 | L34: =IF(AND(10>=$E$8,10<=$F$8),$D$8/($F$8-$E$8+1),0) -> 0 | M34: =IF(AND(11>=$E$8,11<=$F$8),$D$8/($F$8-$E$8+1),0) -> 0 | N34: =IF(AND(12>=$E$8,12<=$F$8),$D$8/($F$8-$E$8+1),0) -> 0
A35: 5 | B35: =B9 -> Payment provider onboarding + real test payments | C35: =IF(AND(1>=$E$9,1<=$F$9),$D$9/($F$9-$E$9+1),0) -> 0 | D35: =IF(AND(2>=$E$9,2<=$F$9),$D$9/($F$9-$E$9+1),0) -> 75000 | E35: =IF(AND(3>=$E$9,3<=$F$9),$D$9/($F$9-$E$9+1),0) -> 75000 | F35: =IF(AND(4>=$E$9,4<=$F$9),$D$9/($F$9-$E$9+1),0) -> 0 | G35: =IF(AND(5>=$E$9,5<=$F$9),$D$9/($F$9-$E$9+1),0) -> 0 | H35: =IF(AND(6>=$E$9,6<=$F$9),$D$9/($F$9-$E$9+1),0) -> 0 | I35: =IF(AND(7>=$E$9,7<=$F$9),$D$9/($F$9-$E$9+1),0) -> 0 | J35: =IF(AND(8>=$E$9,8<=$F$9),$D$9/($F$9-$E$9+1),0) -> 0 | K35: =IF(AND(9>=$E$9,9<=$F$9),$D$9/($F$9-$E$9+1),0) -> 0 | L35: =IF(AND(10>=$E$9,10<=$F$9),$D$9/($F$9-$E$9+1),0) -> 0 | M35: =IF(AND(11>=$E$9,11<=$F$9),$D$9/($F$9-$E$9+1),0) -> 0 | N35: =IF(AND(12>=$E$9,12<=$F$9),$D$9/($F$9-$E$9+1),0) -> 0
A36: 6 | B36: =B10 -> Guide videos + tour photos (4 guides, 4 tours) | C36: =IF(AND(1>=$E$10,1<=$F$10),$D$10/($F$10-$E$10+1),0) -> 0 | D36: =IF(AND(2>=$E$10,2<=$F$10),$D$10/($F$10-$E$10+1),0) -> 250000 | E36: =IF(AND(3>=$E$10,3<=$F$10),$D$10/($F$10-$E$10+1),0) -> 250000 | F36: =IF(AND(4>=$E$10,4<=$F$10),$D$10/($F$10-$E$10+1),0) -> 0 | G36: =IF(AND(5>=$E$10,5<=$F$10),$D$10/($F$10-$E$10+1),0) -> 0 | H36: =IF(AND(6>=$E$10,6<=$F$10),$D$10/($F$10-$E$10+1),0) -> 0 | I36: =IF(AND(7>=$E$10,7<=$F$10),$D$10/($F$10-$E$10+1),0) -> 0 | J36: =IF(AND(8>=$E$10,8<=$F$10),$D$10/($F$10-$E$10+1),0) -> 0 | K36: =IF(AND(9>=$E$10,9<=$F$10),$D$10/($F$10-$E$10+1),0) -> 0 | L36: =IF(AND(10>=$E$10,10<=$F$10),$D$10/($F$10-$E$10+1),0) -> 0 | M36: =IF(AND(11>=$E$10,11<=$F$10),$D$10/($F$10-$E$10+1),0) -> 0 | N36: =IF(AND(12>=$E$10,12<=$F$10),$D$10/($F$10-$E$10+1),0) -> 0
A37: 7 | B37: =B11 -> Pre-launch security review | C37: =IF(AND(1>=$E$11,1<=$F$11),$D$11/($F$11-$E$11+1),0) -> 0 | D37: =IF(AND(2>=$E$11,2<=$F$11),$D$11/($F$11-$E$11+1),0) -> 0 | E37: =IF(AND(3>=$E$11,3<=$F$11),$D$11/($F$11-$E$11+1),0) -> 250000 | F37: =IF(AND(4>=$E$11,4<=$F$11),$D$11/($F$11-$E$11+1),0) -> 0 | G37: =IF(AND(5>=$E$11,5<=$F$11),$D$11/($F$11-$E$11+1),0) -> 0 | H37: =IF(AND(6>=$E$11,6<=$F$11),$D$11/($F$11-$E$11+1),0) -> 0 | I37: =IF(AND(7>=$E$11,7<=$F$11),$D$11/($F$11-$E$11+1),0) -> 0 | J37: =IF(AND(8>=$E$11,8<=$F$11),$D$11/($F$11-$E$11+1),0) -> 0 | K37: =IF(AND(9>=$E$11,9<=$F$11),$D$11/($F$11-$E$11+1),0) -> 0 | L37: =IF(AND(10>=$E$11,10<=$F$11),$D$11/($F$11-$E$11+1),0) -> 0 | M37: =IF(AND(11>=$E$11,11<=$F$11),$D$11/($F$11-$E$11+1),0) -> 0 | N37: =IF(AND(12>=$E$11,12<=$F$11),$D$11/($F$11-$E$11+1),0) -> 0
A38: 8 | B38: =B12 -> Interviews + usability tests (incentives, recruiting) | C38: =IF(AND(1>=$E$12,1<=$F$12),$D$12/($F$12-$E$12+1),0) -> 83333.333 | D38: =IF(AND(2>=$E$12,2<=$F$12),$D$12/($F$12-$E$12+1),0) -> 83333.333 | E38: =IF(AND(3>=$E$12,3<=$F$12),$D$12/($F$12-$E$12+1),0) -> 83333.333 | F38: =IF(AND(4>=$E$12,4<=$F$12),$D$12/($F$12-$E$12+1),0) -> 0 | G38: =IF(AND(5>=$E$12,5<=$F$12),$D$12/($F$12-$E$12+1),0) -> 0 | H38: =IF(AND(6>=$E$12,6<=$F$12),$D$12/($F$12-$E$12+1),0) -> 0 | I38: =IF(AND(7>=$E$12,7<=$F$12),$D$12/($F$12-$E$12+1),0) -> 0 | J38: =IF(AND(8>=$E$12,8<=$F$12),$D$12/($F$12-$E$12+1),0) -> 0 | K38: =IF(AND(9>=$E$12,9<=$F$12),$D$12/($F$12-$E$12+1),0) -> 0 | L38: =IF(AND(10>=$E$12,10<=$F$12),$D$12/($F$12-$E$12+1),0) -> 0 | M38: =IF(AND(11>=$E$12,11<=$F$12),$D$12/($F$12-$E$12+1),0) -> 0 | N38: =IF(AND(12>=$E$12,12<=$F$12),$D$12/($F$12-$E$12+1),0) -> 0
A39: 9 | B39: =B13 -> Xiaohongshu content + KOC collaborations | C39: =IF(AND(1>=$E$13,1<=$F$13),$D$13/($F$13-$E$13+1),0) -> 0 | D39: =IF(AND(2>=$E$13,2<=$F$13),$D$13/($F$13-$E$13+1),0) -> 0 | E39: =IF(AND(3>=$E$13,3<=$F$13),$D$13/($F$13-$E$13+1),0) -> 0 | F39: =IF(AND(4>=$E$13,4<=$F$13),$D$13/($F$13-$E$13+1),0) -> 133333.33 | G39: =IF(AND(5>=$E$13,5<=$F$13),$D$13/($F$13-$E$13+1),0) -> 133333.33 | H39: =IF(AND(6>=$E$13,6<=$F$13),$D$13/($F$13-$E$13+1),0) -> 133333.33 | I39: =IF(AND(7>=$E$13,7<=$F$13),$D$13/($F$13-$E$13+1),0) -> 133333.33 | J39: =IF(AND(8>=$E$13,8<=$F$13),$D$13/($F$13-$E$13+1),0) -> 133333.33 | K39: =IF(AND(9>=$E$13,9<=$F$13),$D$13/($F$13-$E$13+1),0) -> 133333.33 | L39: =IF(AND(10>=$E$13,10<=$F$13),$D$13/($F$13-$E$13+1),0) -> 133333.33 | M39: =IF(AND(11>=$E$13,11<=$F$13),$D$13/($F$13-$E$13+1),0) -> 133333.33 | N39: =IF(AND(12>=$E$13,12<=$F$13),$D$13/($F$13-$E$13+1),0) -> 133333.33
A40: 10 | B40: =B14 -> Printed postcards + QR cards | C40: =IF(AND(1>=$E$14,1<=$F$14),$D$14/($F$14-$E$14+1),0) -> 0 | D40: =IF(AND(2>=$E$14,2<=$F$14),$D$14/($F$14-$E$14+1),0) -> 0 | E40: =IF(AND(3>=$E$14,3<=$F$14),$D$14/($F$14-$E$14+1),0) -> 0 | F40: =IF(AND(4>=$E$14,4<=$F$14),$D$14/($F$14-$E$14+1),0) -> 100000 | G40: =IF(AND(5>=$E$14,5<=$F$14),$D$14/($F$14-$E$14+1),0) -> 0 | H40: =IF(AND(6>=$E$14,6<=$F$14),$D$14/($F$14-$E$14+1),0) -> 0 | I40: =IF(AND(7>=$E$14,7<=$F$14),$D$14/($F$14-$E$14+1),0) -> 0 | J40: =IF(AND(8>=$E$14,8<=$F$14),$D$14/($F$14-$E$14+1),0) -> 0 | K40: =IF(AND(9>=$E$14,9<=$F$14),$D$14/($F$14-$E$14+1),0) -> 0 | L40: =IF(AND(10>=$E$14,10<=$F$14),$D$14/($F$14-$E$14+1),0) -> 0 | M40: =IF(AND(11>=$E$14,11<=$F$14),$D$14/($F$14-$E$14+1),0) -> 0 | N40: =IF(AND(12>=$E$14,12<=$F$14),$D$14/($F$14-$E$14+1),0) -> 0
A41: 11 | B41: =B15 -> Hosting, CDN, database, domain, e-mail, monitoring | C41: =IF(AND(1>=$E$15,1<=$F$15),$D$15/($F$15-$E$15+1),0) -> 25000 | D41: =IF(AND(2>=$E$15,2<=$F$15),$D$15/($F$15-$E$15+1),0) -> 25000 | E41: =IF(AND(3>=$E$15,3<=$F$15),$D$15/($F$15-$E$15+1),0) -> 25000 | F41: =IF(AND(4>=$E$15,4<=$F$15),$D$15/($F$15-$E$15+1),0) -> 25000 | G41: =IF(AND(5>=$E$15,5<=$F$15),$D$15/($F$15-$E$15+1),0) -> 25000 | H41: =IF(AND(6>=$E$15,6<=$F$15),$D$15/($F$15-$E$15+1),0) -> 25000 | I41: =IF(AND(7>=$E$15,7<=$F$15),$D$15/($F$15-$E$15+1),0) -> 25000 | J41: =IF(AND(8>=$E$15,8<=$F$15),$D$15/($F$15-$E$15+1),0) -> 25000 | K41: =IF(AND(9>=$E$15,9<=$F$15),$D$15/($F$15-$E$15+1),0) -> 25000 | L41: =IF(AND(10>=$E$15,10<=$F$15),$D$15/($F$15-$E$15+1),0) -> 25000 | M41: =IF(AND(11>=$E$15,11<=$F$15),$D$15/($F$15-$E$15+1),0) -> 25000 | N41: =IF(AND(12>=$E$15,12<=$F$15),$D$15/($F$15-$E$15+1),0) -> 25000
A42: 12 | B42: =B16 -> Chinese-speaking support, part-time | C42: =IF(AND(1>=$E$16,1<=$F$16),$D$16/($F$16-$E$16+1),0) -> 0 | D42: =IF(AND(2>=$E$16,2<=$F$16),$D$16/($F$16-$E$16+1),0) -> 0 | E42: =IF(AND(3>=$E$16,3<=$F$16),$D$16/($F$16-$E$16+1),0) -> 0 | F42: =IF(AND(4>=$E$16,4<=$F$16),$D$16/($F$16-$E$16+1),0) -> 120000 | G42: =IF(AND(5>=$E$16,5<=$F$16),$D$16/($F$16-$E$16+1),0) -> 120000 | H42: =IF(AND(6>=$E$16,6<=$F$16),$D$16/($F$16-$E$16+1),0) -> 120000 | I42: =IF(AND(7>=$E$16,7<=$F$16),$D$16/($F$16-$E$16+1),0) -> 120000 | J42: =IF(AND(8>=$E$16,8<=$F$16),$D$16/($F$16-$E$16+1),0) -> 120000 | K42: =IF(AND(9>=$E$16,9<=$F$16),$D$16/($F$16-$E$16+1),0) -> 120000 | L42: =IF(AND(10>=$E$16,10<=$F$16),$D$16/($F$16-$E$16+1),0) -> 120000 | M42: =IF(AND(11>=$E$16,11<=$F$16),$D$16/($F$16-$E$16+1),0) -> 120000 | N42: =IF(AND(12>=$E$16,12<=$F$16),$D$16/($F$16-$E$16+1),0) -> 120000
A43: 13 | B43: =B17 -> Contingency reserve (assumed fully used) | C43: =IF(AND(1>=$E$17,1<=$F$17),$D$17/($F$17-$E$17+1),0) -> 0 | D43: =IF(AND(2>=$E$17,2<=$F$17),$D$17/($F$17-$E$17+1),0) -> 0 | E43: =IF(AND(3>=$E$17,3<=$F$17),$D$17/($F$17-$E$17+1),0) -> 62000 | F43: =IF(AND(4>=$E$17,4<=$F$17),$D$17/($F$17-$E$17+1),0) -> 62000 | G43: =IF(AND(5>=$E$17,5<=$F$17),$D$17/($F$17-$E$17+1),0) -> 62000 | H43: =IF(AND(6>=$E$17,6<=$F$17),$D$17/($F$17-$E$17+1),0) -> 62000 | I43: =IF(AND(7>=$E$17,7<=$F$17),$D$17/($F$17-$E$17+1),0) -> 62000 | J43: =IF(AND(8>=$E$17,8<=$F$17),$D$17/($F$17-$E$17+1),0) -> 62000 | K43: =IF(AND(9>=$E$17,9<=$F$17),$D$17/($F$17-$E$17+1),0) -> 62000 | L43: =IF(AND(10>=$E$17,10<=$F$17),$D$17/($F$17-$E$17+1),0) -> 62000 | M43: =IF(AND(11>=$E$17,11<=$F$17),$D$17/($F$17-$E$17+1),0) -> 62000 | N43: =IF(AND(12>=$E$17,12<=$F$17),$D$17/($F$17-$E$17+1),0) -> 62000
...

Sheet Cashflow
A1: Monthly cash flow, three scenarios (KZT)
A2: Travelers = volume % × target run-rate × ramp share. Ramp: linear from launch month to month 24 (shifted by any launch delay), flat afterwards. Contribution = travelers × price × margin.
C3: Company target (100%) | I3: Worst case −30% (required) | O3: Stress test
A4: Month | B4: Platform costs (year 1 = budget spend; later = running costs + marketing) | C4: Target: Travelers | D4: Target: Gross bookings | E4: Target: Contribution | F4: Target: Cash flow | G4: Target: Cumulative cash flow | H4: Target: Monthly CF ≥ 0 (1/0) | I4: −30%: Travelers | J4: −30%: Gross bookings | K4: −30%: Contribution | L4: −30%: Cash flow | M4: −30%: Cumulative cash flow | N4: −30%: Monthly CF ≥ 0 (1/0) | O4: Stress: Travelers | P4: Stress: Gross bookings | Q4: Stress: Contribution | R4: Stress: Cash flow | S4: Stress: Cumulative cash flow | T4: Stress: Monthly CF ≥ 0 (1/0)
A5: 1 | B5: =IF(A5<=12,INDEX(Budget_8M!$C$44:$N$44,A5),Inputs!$B$24) -> 1158333.3 | C5: =IF(A5<Inputs!$B$9+Inputs!$D$29,0,Inputs!$B$29*Inputs!$B$23*MIN(1,(A5-Inputs!$B$9-Inputs!$D$29+1)/(Inputs!$B$10-Inputs!$B$9+1))) -> 0 | D5: =C5*Inputs!$B$4 -> 0 | E5: =D5*Inputs!$C$29 -> 0 | F5: =E5-$B5 -> -1158333.3 | G5: =F5 -> -1158333.3 | H5: =IF(F5>=0,1,0) -> 0 | I5: =IF(A5<Inputs!$B$9+Inputs!$D$30,0,Inputs!$B$30*Inputs!$B$23*MIN(1,(A5-Inputs!$B$9-Inputs!$D$30+1)/(Inputs!$B$10-Inputs!$B$9+1))) -> 0 | J5: =I5*Inputs!$B$4 -> 0 | K5: =J5*Inputs!$C$30 -> 0 | L5: =K5-$B5 -> -1158333.3 | M5: =L5 -> -1158333.3 | N5: =IF(L5>=0,1,0) -> 0 | O5: =IF(A5<Inputs!$B$9+Inputs!$D$31,0,Inputs!$B$31*Inputs!$B$23*MIN(1,(A5-Inputs!$B$9-Inputs!$D$31+1)/(Inputs!$B$10-Inputs!$B$9+1))) -> 0 | P5: =O5*Inputs!$B$4 -> 0 | Q5: =P5*Inputs!$C$31 -> 0 | R5: =Q5-$B5 -> -1158333.3 | S5: =R5 -> -1158333.3 | T5: =IF(R5>=0,1,0) -> 0
A6: 2 | B6: =IF(A6<=12,INDEX(Budget_8M!$C$44:$N$44,A6),Inputs!$B$24) -> 1783333.3 | C6: =IF(A6<Inputs!$B$9+Inputs!$D$29,0,Inputs!$B$29*Inputs!$B$23*MIN(1,(A6-Inputs!$B$9-Inputs!$D$29+1)/(Inputs!$B$10-Inputs!$B$9+1))) -> 0 | D6: =C6*Inputs!$B$4 -> 0 | E6: =D6*Inputs!$C$29 -> 0 | F6: =E6-$B6 -> -1783333.3 | G6: =G5+F6 -> -2941666.7 | H6: =IF(F6>=0,1,0) -> 0 | I6: =IF(A6<Inputs!$B$9+Inputs!$D$30,0,Inputs!$B$30*Inputs!$B$23*MIN(1,(A6-Inputs!$B$9-Inputs!$D$30+1)/(Inputs!$B$10-Inputs!$B$9+1))) -> 0 | J6: =I6*Inputs!$B$4 -> 0 | K6: =J6*Inputs!$C$30 -> 0 | L6: =K6-$B6 -> -1783333.3 | M6: =M5+L6 -> -2941666.7 | N6: =IF(L6>=0,1,0) -> 0 | O6: =IF(A6<Inputs!$B$9+Inputs!$D$31,0,Inputs!$B$31*Inputs!$B$23*MIN(1,(A6-Inputs!$B$9-Inputs!$D$31+1)/(Inputs!$B$10-Inputs!$B$9+1))) -> 0 | P6: =O6*Inputs!$B$4 -> 0 | Q6: =P6*Inputs!$C$31 -> 0 | R6: =Q6-$B6 -> -1783333.3 | S6: =S5+R6 -> -2941666.7 | T6: =IF(R6>=0,1,0) -> 0
A7: 3 | B7: =IF(A7<=12,INDEX(Budget_8M!$C$44:$N$44,A7),Inputs!$B$24) -> 1895333.3 | C7: =IF(A7<Inputs!$B$9+Inputs!$D$29,0,Inputs!$B$29*Inputs!$B$23*MIN(1,(A7-Inputs!$B$9-Inputs!$D$29+1)/(Inputs!$B$10-Inputs!$B$9+1))) -> 0 | D7: =C7*Inputs!$B$4 -> 0 | E7: =D7*Inputs!$C$29 -> 0 | F7: =E7-$B7 -> -1895333.3 | G7: =G6+F7 -> -4837000 | H7: =IF(F7>=0,1,0) -> 0 | I7: =IF(A7<Inputs!$B$9+Inputs!$D$30,0,Inputs!$B$30*Inputs!$B$23*MIN(1,(A7-Inputs!$B$9-Inputs!$D$30+1)/(Inputs!$B$10-Inputs!$B$9+1))) -> 0 | J7: =I7*Inputs!$B$4 -> 0 | K7: =J7*Inputs!$C$30 -> 0 | L7: =K7-$B7 -> -1895333.3 | M7: =M6+L7 -> -4837000 | N7: =IF(L7>=0,1,0) -> 0 | O7: =IF(A7<Inputs!$B$9+Inputs!$D$31,0,Inputs!$B$31*Inputs!$B$23*MIN(1,(A7-Inputs!$B$9-Inputs!$D$31+1)/(Inputs!$B$10-Inputs!$B$9+1))) -> 0 | P7: =O7*Inputs!$B$4 -> 0 | Q7: =P7*Inputs!$C$31 -> 0 | R7: =Q7-$B7 -> -1895333.3 | S7: =S6+R7 -> -4837000 | T7: =IF(R7>=0,1,0) -> 0
A8: 4 | B8: =IF(A8<=12,INDEX(Budget_8M!$C$44:$N$44,A8),Inputs!$B$24) -> 440333.33 | C8: =IF(A8<Inputs!$B$9+Inputs!$D$29,0,Inputs!$B$29*Inputs!$B$23*MIN(1,(A8-Inputs!$B$9-Inputs!$D$29+1)/(Inputs!$B$10-Inputs!$B$9+1))) -> 5.0113379 | D8: =C8*Inputs!$B$4 -> 220498.87 | E8: =D8*Inputs!$C$29 -> 66149.66 | F8: =E8-$B8 -> -374183.67 | G8: =G7+F8 -> -5211183.7 | H8: =IF(F8>=0,1,0) -> 0 | I8: =IF(A8<Inputs!$B$9+Inputs!$D$30,0,Inputs!$B$30*Inputs!$B$23*MIN(1,(A8-Inputs!$B$9-Inputs!$D$30+1)/(Inputs!$B$10-Inputs!$B$9+1))) -> 3.5079365 | J8: =I8*Inputs!$B$4 -> 154349.21 | K8: =J8*Inputs!$C$30 -> 46304.762 | L8: =K8-$B8 -> -394028.57 | M8: =M7+L8 -> -5231028.6 | N8: =IF(L8>=0,1,0) -> 0 | O8: =IF(A8<Inputs!$B$9+Inputs!$D$31,0,Inputs!$B$31*Inputs!$B$23*MIN(1,(A8-Inputs!$B$9-Inputs!$D$31+1)/(Inputs!$B$10-Inputs!$B$9+1))) -> 0 | P8: =O8*Inputs!$B$4 -> 0 | Q8: =P8*Inputs!$C$31 -> 0 | R8: =Q8-$B8 -> -440333.33 | S8: =S7+R8 -> -5277333.3 | T8: =IF(R8>=0,1,0) -> 0
A9: 5 | B9: =IF(A9<=12,INDEX(Budget_8M!$C$44:$N$44,A9),Inputs!$B$24) -> 340333.33 | C9: =IF(A9<Inputs!$B$9+Inputs!$D$29,0,Inputs!$B$29*Inputs!$B$23*MIN(1,(A9-Inputs!$B$9-Inputs!$D$29+1)/(Inputs!$B$10-Inputs!$B$9+1))) -> 10.022676 | D9: =C9*Inputs!$B$4 -> 440997.73 | E9: =D9*Inputs!$C$29 -> 132299.32 | F9: =E9-$B9 -> -208034.01 | G9: =G8+F9 -> -5419217.7 | H9: =IF(F9>=0,1,0) -> 0 | I9: =IF(A9<Inputs!$B$9+Inputs!$D$30,0,Inputs!$B$30*Inputs!$B$23*MIN(1,(A9-Inputs!$B$9-Inputs!$D$30+1)/(Inputs!$B$10-Inputs!$B$9+1))) -> 7.015873 | J9: =I9*Inputs!$B$4 -> 308698.41 | K9: =J9*Inputs!$C$30 -> 92609.524 | L9: =K9-$B9 -> -247723.81 | M9: =M8+L9 -> -5478752.4 | N9: =IF(L9>=0,1,0) -> 0 | O9: =IF(A9<Inputs!$B$9+Inputs!$D$31,0,Inputs!$B$31*Inputs!$B$23*MIN(1,(A9-Inputs!$B$9-Inputs!$D$31+1)/(Inputs!$B$10-Inputs!$B$9+1))) -> 0 | P9: =O9*Inputs!$B$4 -> 0 | Q9: =P9*Inputs!$C$31 -> 0 | R9: =Q9-$B9 -> -340333.33 | S9: =S8+R9 -> -5617666.7 | T9: =IF(R9>=0,1,0) -> 0
A10: 6 | B10: =IF(A10<=12,INDEX(Budget_8M!$C$44:$N$44,A10),Inputs!$B$24) -> 340333.33 | C10: =IF(A10<Inputs!$B$9+Inputs!$D$29,0,Inputs!$B$29*Inputs!$B$23*MIN(1,(A10-Inputs!$B$9-Inputs!$D$29+1)/(Inputs!$B$10-Inputs!$B$9+1))) -> 15.034014 | D10: =C10*Inputs!$B$4 -> 661496.6 | E10: =D10*Inputs!$C$29 -> 198448.98 | F10: =E10-$B10 -> -141884.35 | G10: =G9+F10 -> -5561102 | H10: =IF(F10>=0,1,0) -> 0 | I10: =IF(A10<Inputs!$B$9+Inputs!$D$30,0,Inputs!$B$30*Inputs!$B$23*MIN(1,(A10-Inputs!$B$9-Inputs!$D$30+1)/(Inputs!$B$10-Inputs!$B$9+1))) -> 10.52381 | J10: =I10*Inputs!$B$4 -> 463047.62 | K10: =J10*Inputs!$C$30 -> 138914.29 | L10: =K10-$B10 -> -201419.05 | M10: =M9+L10 -> -5680171.4 | N10: =IF(L10>=0,1,0) -> 0 | O10: =IF(A10<Inputs!$B$9+Inputs!$D$31,0,Inputs!$B$31*Inputs!$B$23*MIN(1,(A10-Inputs!$B$9-Inputs!$D$31+1)/(Inputs!$B$10-Inputs!$B$9+1))) -> 2.0045351 | P10: =O10*Inputs!$B$4 -> 88199.546 | Q10: =P10*Inputs!$C$31 -> 22049.887 | R10: =Q10-$B10 -> -318283.45 | S10: =S9+R10 -> -5935950.1 | T10: =IF(R10>=0,1,0) -> 0
A11: 7 | B11: =IF(A11<=12,INDEX(Budget_8M!$C$44:$N$44,A11),Inputs!$B$24) -> 340333.33 | C11: =IF(A11<Inputs!$B$9+Inputs!$D$29,0,Inputs!$B$29*Inputs!$B$23*MIN(1,(A11-Inputs!$B$9-Inputs!$D$29+1)/(Inputs!$B$10-Inputs!$B$9+1))) -> 20.045351 | D11: =C11*Inputs!$B$4 -> 881995.46 | E11: =D11*Inputs!$C$29 -> 264598.64 | F11: =E11-$B11 -> -75734.694 | G11: =G10+F11 -> -5636836.7 | H11: =IF(F11>=0,1,0) -> 0 | I11: =IF(A11<Inputs!$B$9+Inputs!$D$30,0,Inputs!$B$30*Inputs!$B$23*MIN(1,(A11-Inputs!$B$9-Inputs!$D$30+1)/(Inputs!$B$10-Inputs!$B$9+1))) -> 14.031746 | J11: =I11*Inputs!$B$4 -> 617396.83 | K11: =J11*Inputs!$C$30 -> 185219.05 | L11: =K11-$B11 -> -155114.29 | M11: =M10+L11 -> -5835285.7 | N11: =IF(L11>=0,1,0) -> 0 | O11: =IF(A11<Inputs!$B$9+Inputs!$D$31,0,Inputs!$B$31*Inputs!$B$23*MIN(1,(A11-Inputs!$B$9-Inputs!$D$31+1)/(Inputs!$B$10-Inputs!$B$9+1))) -> 4.0090703 | P11: =O11*Inputs!$B$4 -> 176399.09 | Q11: =P11*Inputs!$C$31 -> 44099.773 | R11: =Q11-$B11 -> -296233.56 | S11: =S10+R11 -> -6232183.7 | T11: =IF(R11>=0,1,0) -> 0
A12: 8 | B12: =IF(A12<=12,INDEX(Budget_8M!$C$44:$N$44,A12),Inputs!$B$24) -> 340333.33 | C12: =IF(A12<Inputs!$B$9+Inputs!$D$29,0,Inputs!$B$29*Inputs!$B$23*MIN(1,(A12-Inputs!$B$9-Inputs!$D$29+1)/(Inputs!$B$10-Inputs!$B$9+1))) -> 25.056689 | D12: =C12*Inputs!$B$4 -> 1102494.3 | E12: =D12*Inputs!$C$29 -> 330748.3 | F12: =E12-$B12 -> -9585.034 | G12: =G11+F12 -> -5646421.8 | H12: =IF(F12>=0,1,0) -> 0 | I12: =IF(A12<Inputs!$B$9+Inputs!$D$30,0,Inputs!$B$30*Inputs!$B$23*MIN(1,(A12-Inputs!$B$9-Inputs!$D$30+1)/(Inputs!$B$10-Inputs!$B$9+1))) -> 17.539683 | J12: =I12*Inputs!$B$4 -> 771746.03 | K12: =J12*Inputs!$C$30 -> 231523.81 | L12: =K12-$B12 -> -108809.52 | M12: =M11+L12 -> -5944095.2 | N12: =IF(L12>=0,1,0) -> 0 | O12: =IF(A12<Inputs!$B$9+Inputs!$D$31,0,Inputs!$B$31*Inputs!$B$23*MIN(1,(A12-Inputs!$B$9-Inputs!$D$31+1)/(Inputs!$B$10-Inputs!$B$9+1))) -> 6.0136054 | P12: =O12*Inputs!$B$4 -> 264598.64 | Q12: =P12*Inputs!$C$31 -> 66149.66 | R12: =Q12-$B12 -> -274183.67 | S12: =S11+R12 -> -6506367.3 | T12: =IF(R12>=0,1,0) -> 0
A13: 9 | B13: =IF(A13<=12,INDEX(Budget_8M!$C$44:$N$44,A13),Inputs!$B$24) -> 340333.33 | C13: =IF(A13<Inputs!$B$9+Inputs!$D$29,0,Inputs!$B$29*Inputs!$B$23*MIN(1,(A13-Inputs!$B$9-Inputs!$D$29+1)/(Inputs!$B$10-Inputs!$B$9+1))) -> 30.068027 | D13: =C13*Inputs!$B$4 -> 1322993.2 | E13: =D13*Inputs!$C$29 -> 396897.96 | F13: =E13-$B13 -> 56564.626 | G13: =G12+F13 -> -5589857.1 | H13: =IF(F13>=0,1,0) -> 1 | I13: =IF(A13<Inputs!$B$9+Inputs!$D$30,0,Inputs!$B$30*Inputs!$B$23*MIN(1,(A13-Inputs!$B$9-Inputs!$D$30+1)/(Inputs!$B$10-Inputs!$B$9+1))) -> 21.047619 | J13: =I13*Inputs!$B$4 -> 926095.24 | K13: =J13*Inputs!$C$30 -> 277828.57 | L13: =K13-$B13 -> -62504.762 | M13: =M12+L13 -> -6006600 | N13: =IF(L13>=0,1,0) -> 0 | O13: =IF(A13<Inputs!$B$9+Inputs!$D$31,0,Inputs!$B$31*Inputs!$B$23*MIN(1,(A13-Inputs!$B$9-Inputs!$D$31+1)/(Inputs!$B$10-Inputs!$B$9+1))) -> 8.0181406 | P13: =O13*Inputs!$B$4 -> 352798.19 | Q13: =P13*Inputs!$C$31 -> 88199.546 | R13: =Q13-$B13 -> -252133.79 | S13: =S12+R13 -> -6758501.1 | T13: =IF(R13>=0,1,0) -> 0
A14: 10 | B14: =IF(A14<=12,INDEX(Budget_8M!$C$44:$N$44,A14),Inputs!$B$24) -> 340333.33 | C14: =IF(A14<Inputs!$B$9+Inputs!$D$29,0,Inputs!$B$29*Inputs!$B$23*MIN(1,(A14-Inputs!$B$9-Inputs!$D$29+1)/(Inputs!$B$10-Inputs!$B$9+1))) -> 35.079365 | D14: =C14*Inputs!$B$4 -> 1543492.1 | E14: =D14*Inputs!$C$29 -> 463047.62 | F14: =E14-$B14 -> 122714.29 | G14: =G13+F14 -> -5467142.9 | H14: =IF(F14>=0,1,0) -> 1 | I14: =IF(A14<Inputs!$B$9+Inputs!$D$30,0,Inputs!$B$30*Inputs!$B$23*MIN(1,(A14-Inputs!$B$9-Inputs!$D$30+1)/(Inputs!$B$10-Inputs!$B$9+1))) -> 24.555556 | J14: =I14*Inputs!$B$4 -> 1080444.4 | K14: =J14*Inputs!$C$30 -> 324133.33 | L14: =K14-$B14 -> -16200 | M14: =M13+L14 -> -6022800 | N14: =IF(L14>=0,1,0) -> 0 | O14: =IF(A14<Inputs!$B$9+Inputs!$D$31,0,Inputs!$B$31*Inputs!$B$23*MIN(1,(A14-Inputs!$B$9-Inputs!$D$31+1)/(Inputs!$B$10-Inputs!$B$9+1))) -> 10.022676 | P14: =O14*Inputs!$B$4 -> 440997.73 | Q14: =P14*Inputs!$C$31 -> 110249.43 | R14: =Q14-$B14 -> -230083.9 | S14: =S13+R14 -> -6988585 | T14: =IF(R14>=0,1,0) -> 0
A15: 11 | B15: =IF(A15<=12,INDEX(Budget_8M!$C$44:$N$44,A15),Inputs!$B$24) -> 340333.33 | C15: =IF(A15<Inputs!$B$9+Inputs!$D$29,0,Inputs!$B$29*Inputs!$B$23*MIN(1,(A15-Inputs!$B$9-Inputs!$D$29+1)/(Inputs!$B$10-Inputs!$B$9+1))) -> 40.090703 | D15: =C15*Inputs!$B$4 -> 1763990.9 | E15: =D15*Inputs!$C$29 -> 529197.28 | F15: =E15-$B15 -> 188863.95 | G15: =G14+F15 -> -5278278.9 | H15: =IF(F15>=0,1,0) -> 1 | I15: =IF(A15<Inputs!$B$9+Inputs!$D$30,0,Inputs!$B$30*Inputs!$B$23*MIN(1,(A15-Inputs!$B$9-Inputs!$D$30+1)/(Inputs!$B$10-Inputs!$B$9+1))) -> 28.063492 | J15: =I15*Inputs!$B$4 -> 1234793.7 | K15: =J15*Inputs!$C$30 -> 370438.1 | L15: =K15-$B15 -> 30104.762 | M15: =M14+L15 -> -5992695.2 | N15: =IF(L15>=0,1,0) -> 1 | O15: =IF(A15<Inputs!$B$9+Inputs!$D$31,0,Inputs!$B$31*Inputs!$B$23*MIN(1,(A15-Inputs!$B$9-Inputs!$D$31+1)/(Inputs!$B$10-Inputs!$B$9+1))) -> 12.027211 | P15: =O15*Inputs!$B$4 -> 529197.28 | Q15: =P15*Inputs!$C$31 -> 132299.32 | R15: =Q15-$B15 -> -208034.01 | S15: =S14+R15 -> -7196619 | T15: =IF(R15>=0,1,0) -> 0
A16: 12 | B16: =IF(A16<=12,INDEX(Budget_8M!$C$44:$N$44,A16),Inputs!$B$24) -> 340333.33 | C16: =IF(A16<Inputs!$B$9+Inputs!$D$29,0,Inputs!$B$29*Inputs!$B$23*MIN(1,(A16-Inputs!$B$9-Inputs!$D$29+1)/(Inputs!$B$10-Inputs!$B$9+1))) -> 45.102041 | D16: =C16*Inputs!$B$4 -> 1984489.8 | E16: =D16*Inputs!$C$29 -> 595346.94 | F16: =E16-$B16 -> 255013.61 | G16: =G15+F16 -> -5023265.3 | H16: =IF(F16>=0,1,0) -> 1 | I16: =IF(A16<Inputs!$B$9+Inputs!$D$30,0,Inputs!$B$30*Inputs!$B$23*MIN(1,(A16-Inputs!$B$9-Inputs!$D$30+1)/(Inputs!$B$10-Inputs!$B$9+1))) -> 31.571429 | J16: =I16*Inputs!$B$4 -> 1389142.9 | K16: =J16*Inputs!$C$30 -> 416742.86 | L16: =K16-$B16 -> 76409.524 | M16: =M15+L16 -> -5916285.7 | N16: =IF(L16>=0,1,0) -> 1 | O16: =IF(A16<Inputs!$B$9+Inputs!$D$31,0,Inputs!$B$31*Inputs!$B$23*MIN(1,(A16-Inputs!$B$9-Inputs!$D$31+1)/(Inputs!$B$10-Inputs!$B$9+1))) -> 14.031746 | P16: =O16*Inputs!$B$4 -> 617396.83 | Q16: =P16*Inputs!$C$31 -> 154349.21 | R16: =Q16-$B16 -> -185984.13 | S16: =S15+R16 -> -7382603.2 | T16: =IF(R16>=0,1,0) -> 0
A17: 13 | B17: =IF(A17<=12,INDEX(Budget_8M!$C$44:$N$44,A17),Inputs!$B$24) -> 395000 | C17: =IF(A17<Inputs!$B$9+Inputs!$D$29,0,Inputs!$B$29*Inputs!$B$23*MIN(1,(A17-Inputs!$B$9-Inputs!$D$29+1)/(Inputs!$B$10-Inputs!$B$9+1))) -> 50.113379 | D17: =C17*Inputs!$B$4 -> 2204988.7 | E17: =D17*Inputs!$C$29 -> 661496.6 | F17: =E17-$B17 -> 266496.6 | G17: =G16+F17 -> -4756768.7 | H17: =IF(F17>=0,1,0) -> 1 | I17: =IF(A17<Inputs!$B$9+Inputs!$D$30,0,Inputs!$B$30*Inputs!$B$23*MIN(1,(A17-Inputs!$B$9-Inputs!$D$30+1)/(Inputs!$B$10-Inputs!$B$9+1))) -> 35.079365 | J17: =I17*Inputs!$B$4 -> 1543492.1 | K17: =J17*Inputs!$C$30 -> 463047.62 | L17: =K17-$B17 -> 68047.619 | M17: =M16+L17 -> -5848238.1 | N17: =IF(L17>=0,1,0) -> 1 | O17: =IF(A17<Inputs!$B$9+Inputs!$D$31,0,Inputs!$B$31*Inputs!$B$23*MIN(1,(A17-Inputs!$B$9-Inputs!$D$31+1)/(Inputs!$B$10-Inputs!$B$9+1))) -> 16.036281 | P17: =O17*Inputs!$B$4 -> 705596.37 | Q17: =P17*Inputs!$C$31 -> 176399.09 | R17: =Q17-$B17 -> -218600.91 | S17: =S16+R17 -> -7601204.1 | T17: =IF(R17>=0,1,0) -> 0
... A64: 60 | B64: =IF(A64<=12,INDEX(Budget_8M!$C$44:$N$44,A64),Inputs!$B$24) -> 395000 | C64: =IF(A64<Inputs!$B$9+Inputs!$D$29,0,Inputs!$B$29*Inputs!$B$23*MIN(1,(A64-Inputs!$B$9-Inputs!$D$29+1)/(Inputs!$B$10-Inputs!$B$9+1))) -> 105.2381 | D64: =C64*Inputs!$B$4 -> 4630476.2 | E64: =D64*Inputs!$C$29 -> 1389142.9 | F64: =E64-$B64 -> 994142.86 | G64: =G63+F64 -> 38329714 | H64: =IF(F64>=0,1,0) -> 1 | I64: =IF(A64<Inputs!$B$9+Inputs!$D$30,0,Inputs!$B$30*Inputs!$B$23*MIN(1,(A64-Inputs!$B$9-Inputs!$D$30+1)/(Inputs!$B$10-Inputs!$B$9+1))) -> 73.666667 | J64: =I64*Inputs!$B$4 -> 3241333.3 | K64: =J64*Inputs!$C$30 -> 972400 | L64: =K64-$B64 -> 577400 | M64: =M63+L64 -> 18742800 | N64: =IF(L64>=0,1,0) -> 1 | O64: =IF(A64<Inputs!$B$9+Inputs!$D$31,0,Inputs!$B$31*Inputs!$B$23*MIN(1,(A64-Inputs!$B$9-Inputs!$D$31+1)/(Inputs!$B$10-Inputs!$B$9+1))) -> 42.095238 | P64: =O64*Inputs!$B$4 -> 1852190.5 | Q64: =P64*Inputs!$C$31 -> 463047.62 | R64: =Q64-$B64 -> 68047.619 | S64: =S63+R64 -> -6122857.1 | T64: =IF(R64>=0,1,0) -> 1

Sheet Sensitivity
A1: Payback month by margin and volume (launch month 4, Phase 1 budget 8M, running costs + marketing from month 13)
A2: Each cell is calculated in the helper block below (60 months). "none" = no payback within 60 months.
A4: Margin \ Volume | B4: 0.4 | C4: 0.55 | D4: 0.7 | E4: 0.85 | F4: 1
A5: 0.2 | B5: =IF(COUNTIF(C13:C72,"<0")>=60,"none",COUNTIF(C13:C72,"<0")+1) -> none | C5: =IF(COUNTIF(D13:D72,"<0")>=60,"none",COUNTIF(D13:D72,"<0")+1) -> none | D5: =IF(COUNTIF(E13:E72,"<0")>=60,"none",COUNTIF(E13:E72,"<0")+1) -> 47 | E5: =IF(COUNTIF(F13:F72,"<0")>=60,"none",COUNTIF(F13:F72,"<0")+1) -> 35 | F5: =IF(COUNTIF(G13:G72,"<0")>=60,"none",COUNTIF(G13:G72,"<0")+1) -> 29
A6: 0.25 | B6: =IF(COUNTIF(H13:H72,"<0")>=60,"none",COUNTIF(H13:H72,"<0")+1) -> none | C6: =IF(COUNTIF(I13:I72,"<0")>=60,"none",COUNTIF(I13:I72,"<0")+1) -> 48 | D6: =IF(COUNTIF(J13:J72,"<0")>=60,"none",COUNTIF(J13:J72,"<0")+1) -> 34 | E6: =IF(COUNTIF(K13:K72,"<0")>=60,"none",COUNTIF(K13:K72,"<0")+1) -> 28 | F6: =IF(COUNTIF(L13:L72,"<0")>=60,"none",COUNTIF(L13:L72,"<0")+1) -> 25
A7: 0.3 | B7: =IF(COUNTIF(M13:M72,"<0")>=60,"none",COUNTIF(M13:M72,"<0")+1) -> none | C7: =IF(COUNTIF(N13:N72,"<0")>=60,"none",COUNTIF(N13:N72,"<0")+1) -> 36 | D7: =IF(COUNTIF(O13:O72,"<0")>=60,"none",COUNTIF(O13:O72,"<0")+1) -> 28 | E7: =IF(COUNTIF(P13:P72,"<0")>=60,"none",COUNTIF(P13:P72,"<0")+1) -> 24 | F7: =IF(COUNTIF(Q13:Q72,"<0")>=60,"none",COUNTIF(Q13:Q72,"<0")+1) -> 22
A8: 0.35 | B8: =IF(COUNTIF(R13:R72,"<0")>=60,"none",COUNTIF(R13:R72,"<0")+1) -> 47 | C8: =IF(COUNTIF(S13:S72,"<0")>=60,"none",COUNTIF(S13:S72,"<0")+1) -> 30 | D8: =IF(COUNTIF(T13:T72,"<0")>=60,"none",COUNTIF(T13:T72,"<0")+1) -> 25 | E8: =IF(COUNTIF(U13:U72,"<0")>=60,"none",COUNTIF(U13:U72,"<0")+1) -> 22 | F8: =IF(COUNTIF(V13:V72,"<0")>=60,"none",COUNTIF(V13:V72,"<0")+1) -> 20
A11: Helper: cumulative cash flow for each margin × volume pair
A12: Month | B12: Costs | C12: m20% v40% | D12: m20% v55% | E12: m20% v70% | F12: m20% v85% | G12: m20% v100% | H12: m25% v40% | I12: m25% v55% | J12: m25% v70% | K12: m25% v85% | L12: m25% v100% | M12: m30% v40% | N12: m30% v55% | O12: m30% v70% | P12: m30% v85% | Q12: m30% v100% | R12: m35% v40% | S12: m35% v55% | T12: m35% v70% | U12: m35% v85% | V12: m35% v100%
A13: 1 | B13: =Cashflow!B5 -> 1158333.3 | C13: =IF($A13<Inputs!$B$9,0,B$4*Inputs!$B$23*MIN(1,($A13-Inputs!$B$9+1)/(Inputs!$B$10-Inputs!$B$9+1)))*Inputs!$B$4*$A$5-$B13 -> -1158333.3 | D13: =IF($A13<Inputs!$B$9,0,C$4*Inputs!$B$23*MIN(1,($A13-Inputs!$B$9+1)/(Inputs!$B$10-Inputs!$B$9+1)))*Inputs!$B$4*$A$5-$B13 -> -1158333.3 | E13: =IF($A13<Inputs!$B$9,0,D$4*Inputs!$B$23*MIN(1,($A13-Inputs!$B$9+1)/(Inputs!$B$10-Inputs!$B$9+1)))*Inputs!$B$4*$A$5-$B13 -> -1158333.3 | F13: =IF($A13<Inputs!$B$9,0,E$4*Inputs!$B$23*MIN(1,($A13-Inputs!$B$9+1)/(Inputs!$B$10-Inputs!$B$9+1)))*Inputs!$B$4*$A$5-$B13 -> -1158333.3 | G13: =IF($A13<Inputs!$B$9,0,F$4*Inputs!$B$23*MIN(1,($A13-Inputs!$B$9+1)/(Inputs!$B$10-Inputs!$B$9+1)))*Inputs!$B$4*$A$5-$B13 -> -1158333.3 | H13: =IF($A13<Inputs!$B$9,0,B$4*Inputs!$B$23*MIN(1,($A13-Inputs!$B$9+1)/(Inputs!$B$10-Inputs!$B$9+1)))*Inputs!$B$4*$A$6-$B13 -> -1158333.3 | I13: =IF($A13<Inputs!$B$9,0,C$4*Inputs!$B$23*MIN(1,($A13-Inputs!$B$9+1)/(Inputs!$B$10-Inputs!$B$9+1)))*Inputs!$B$4*$A$6-$B13 -> -1158333.3 | J13: =IF($A13<Inputs!$B$9,0,D$4*Inputs!$B$23*MIN(1,($A13-Inputs!$B$9+1)/(Inputs!$B$10-Inputs!$B$9+1)))*Inputs!$B$4*$A$6-$B13 -> -1158333.3 | K13: =IF($A13<Inputs!$B$9,0,E$4*Inputs!$B$23*MIN(1,($A13-Inputs!$B$9+1)/(Inputs!$B$10-Inputs!$B$9+1)))*Inputs!$B$4*$A$6-$B13 -> -1158333.3 | L13: =IF($A13<Inputs!$B$9,0,F$4*Inputs!$B$23*MIN(1,($A13-Inputs!$B$9+1)/(Inputs!$B$10-Inputs!$B$9+1)))*Inputs!$B$4*$A$6-$B13 -> -1158333.3 | M13: =IF($A13<Inputs!$B$9,0,B$4*Inputs!$B$23*MIN(1,($A13-Inputs!$B$9+1)/(Inputs!$B$10-Inputs!$B$9+1)))*Inputs!$B$4*$A$7-$B13 -> -1158333.3 | N13: =IF($A13<Inputs!$B$9,0,C$4*Inputs!$B$23*MIN(1,($A13-Inputs!$B$9+1)/(Inputs!$B$10-Inputs!$B$9+1)))*Inputs!$B$4*$A$7-$B13 -> -1158333.3 | O13: =IF($A13<Inputs!$B$9,0,D$4*Inputs!$B$23*MIN(1,($A13-Inputs!$B$9+1)/(Inputs!$B$10-Inputs!$B$9+1)))*Inputs!$B$4*$A$7-$B13 -> -1158333.3 | P13: =IF($A13<Inputs!$B$9,0,E$4*Inputs!$B$23*MIN(1,($A13-Inputs!$B$9+1)/(Inputs!$B$10-Inputs!$B$9+1)))*Inputs!$B$4*$A$7-$B13 -> -1158333.3 | Q13: =IF($A13<Inputs!$B$9,0,F$4*Inputs!$B$23*MIN(1,($A13-Inputs!$B$9+1)/(Inputs!$B$10-Inputs!$B$9+1)))*Inputs!$B$4*$A$7-$B13 -> -1158333.3 | R13: =IF($A13<Inputs!$B$9,0,B$4*Inputs!$B$23*MIN(1,($A13-Inputs!$B$9+1)/(Inputs!$B$10-Inputs!$B$9+1)))*Inputs!$B$4*$A$8-$B13 -> -1158333.3 | S13: =IF($A13<Inputs!$B$9,0,C$4*Inputs!$B$23*MIN(1,($A13-Inputs!$B$9+1)/(Inputs!$B$10-Inputs!$B$9+1)))*Inputs!$B$4*$A$8-$B13 -> -1158333.3 | T13: =IF($A13<Inputs!$B$9,0,D$4*Inputs!$B$23*MIN(1,($A13-Inputs!$B$9+1)/(Inputs!$B$10-Inputs!$B$9+1)))*Inputs!$B$4*$A$8-$B13 -> -1158333.3 | U13: =IF($A13<Inputs!$B$9,0,E$4*Inputs!$B$23*MIN(1,($A13-Inputs!$B$9+1)/(Inputs!$B$10-Inputs!$B$9+1)))*Inputs!$B$4*$A$8-$B13 -> -1158333.3 | V13: =IF($A13<Inputs!$B$9,0,F$4*Inputs!$B$23*MIN(1,($A13-Inputs!$B$9+1)/(Inputs!$B$10-Inputs!$B$9+1)))*Inputs!$B$4*$A$8-$B13 -> -1158333.3
A14: 2 | B14: =Cashflow!B6 -> 1783333.3 | C14: =C13+IF($A14<Inputs!$B$9,0,B$4*Inputs!$B$23*MIN(1,($A14-Inputs!$B$9+1)/(Inputs!$B$10-Inputs!$B$9+1)))*Inputs!$B$4*$A$5-$B14 -> -2941666.7 | D14: =D13+IF($A14<Inputs!$B$9,0,C$4*Inputs!$B$23*MIN(1,($A14-Inputs!$B$9+1)/(Inputs!$B$10-Inputs!$B$9+1)))*Inputs!$B$4*$A$5-$B14 -> -2941666.7 | E14: =E13+IF($A14<Inputs!$B$9,0,D$4*Inputs!$B$23*MIN(1,($A14-Inputs!$B$9+1)/(Inputs!$B$10-Inputs!$B$9+1)))*Inputs!$B$4*$A$5-$B14 -> -2941666.7 | F14: =F13+IF($A14<Inputs!$B$9,0,E$4*Inputs!$B$23*MIN(1,($A14-Inputs!$B$9+1)/(Inputs!$B$10-Inputs!$B$9+1)))*Inputs!$B$4*$A$5-$B14 -> -2941666.7 | G14: =G13+IF($A14<Inputs!$B$9,0,F$4*Inputs!$B$23*MIN(1,($A14-Inputs!$B$9+1)/(Inputs!$B$10-Inputs!$B$9+1)))*Inputs!$B$4*$A$5-$B14 -> -2941666.7 | H14: =H13+IF($A14<Inputs!$B$9,0,B$4*Inputs!$B$23*MIN(1,($A14-Inputs!$B$9+1)/(Inputs!$B$10-Inputs!$B$9+1)))*Inputs!$B$4*$A$6-$B14 -> -2941666.7 | I14: =I13+IF($A14<Inputs!$B$9,0,C$4*Inputs!$B$23*MIN(1,($A14-Inputs!$B$9+1)/(Inputs!$B$10-Inputs!$B$9+1)))*Inputs!$B$4*$A$6-$B14 -> -2941666.7 | J14: =J13+IF($A14<Inputs!$B$9,0,D$4*Inputs!$B$23*MIN(1,($A14-Inputs!$B$9+1)/(Inputs!$B$10-Inputs!$B$9+1)))*Inputs!$B$4*$A$6-$B14 -> -2941666.7 | K14: =K13+IF($A14<Inputs!$B$9,0,E$4*Inputs!$B$23*MIN(1,($A14-Inputs!$B$9+1)/(Inputs!$B$10-Inputs!$B$9+1)))*Inputs!$B$4*$A$6-$B14 -> -2941666.7 | L14: =L13+IF($A14<Inputs!$B$9,0,F$4*Inputs!$B$23*MIN(1,($A14-Inputs!$B$9+1)/(Inputs!$B$10-Inputs!$B$9+1)))*Inputs!$B$4*$A$6-$B14 -> -2941666.7 | M14: =M13+IF($A14<Inputs!$B$9,0,B$4*Inputs!$B$23*MIN(1,($A14-Inputs!$B$9+1)/(Inputs!$B$10-Inputs!$B$9+1)))*Inputs!$B$4*$A$7-$B14 -> -2941666.7 | N14: =N13+IF($A14<Inputs!$B$9,0,C$4*Inputs!$B$23*MIN(1,($A14-Inputs!$B$9+1)/(Inputs!$B$10-Inputs!$B$9+1)))*Inputs!$B$4*$A$7-$B14 -> -2941666.7 | O14: =O13+IF($A14<Inputs!$B$9,0,D$4*Inputs!$B$23*MIN(1,($A14-Inputs!$B$9+1)/(Inputs!$B$10-Inputs!$B$9+1)))*Inputs!$B$4*$A$7-$B14 -> -2941666.7 | P14: =P13+IF($A14<Inputs!$B$9,0,E$4*Inputs!$B$23*MIN(1,($A14-Inputs!$B$9+1)/(Inputs!$B$10-Inputs!$B$9+1)))*Inputs!$B$4*$A$7-$B14 -> -2941666.7 | Q14: =Q13+IF($A14<Inputs!$B$9,0,F$4*Inputs!$B$23*MIN(1,($A14-Inputs!$B$9+1)/(Inputs!$B$10-Inputs!$B$9+1)))*Inputs!$B$4*$A$7-$B14 -> -2941666.7 | R14: =R13+IF($A14<Inputs!$B$9,0,B$4*Inputs!$B$23*MIN(1,($A14-Inputs!$B$9+1)/(Inputs!$B$10-Inputs!$B$9+1)))*Inputs!$B$4*$A$8-$B14 -> -2941666.7 | S14: =S13+IF($A14<Inputs!$B$9,0,C$4*Inputs!$B$23*MIN(1,($A14-Inputs!$B$9+1)/(Inputs!$B$10-Inputs!$B$9+1)))*Inputs!$B$4*$A$8-$B14 -> -2941666.7 | T14: =T13+IF($A14<Inputs!$B$9,0,D$4*Inputs!$B$23*MIN(1,($A14-Inputs!$B$9+1)/(Inputs!$B$10-Inputs!$B$9+1)))*Inputs!$B$4*$A$8-$B14 -> -2941666.7 | U14: =U13+IF($A14<Inputs!$B$9,0,E$4*Inputs!$B$23*MIN(1,($A14-Inputs!$B$9+1)/(Inputs!$B$10-Inputs!$B$9+1)))*Inputs!$B$4*$A$8-$B14 -> -2941666.7 | V14: =V13+IF($A14<Inputs!$B$9,0,F$4*Inputs!$B$23*MIN(1,($A14-Inputs!$B$9+1)/(Inputs!$B$10-Inputs!$B$9+1)))*Inputs!$B$4*$A$8-$B14 -> -2941666.7
A15: 3 | B15: =Cashflow!B7 -> 1895333.3 | C15: =C14+IF($A15<Inputs!$B$9,0,B$4*Inputs!$B$23*MIN(1,($A15-Inputs!$B$9+1)/(Inputs!$B$10-Inputs!$B$9+1)))*Inputs!$B$4*$A$5-$B15 -> -4837000 | D15: =D14+IF($A15<Inputs!$B$9,0,C$4*Inputs!$B$23*MIN(1,($A15-Inputs!$B$9+1)/(Inputs!$B$10-Inputs!$B$9+1)))*Inputs!$B$4*$A$5-$B15 -> -4837000 | E15: =E14+IF($A15<Inputs!$B$9,0,D$4*Inputs!$B$23*MIN(1,($A15-Inputs!$B$9+1)/(Inputs!$B$10-Inputs!$B$9+1)))*Inputs!$B$4*$A$5-$B15 -> -4837000 | F15: =F14+IF($A15<Inputs!$B$9,0,E$4*Inputs!$B$23*MIN(1,($A15-Inputs!$B$9+1)/(Inputs!$B$10-Inputs!$B$9+1)))*Inputs!$B$4*$A$5-$B15 -> -4837000 | G15: =G14+IF($A15<Inputs!$B$9,0,F$4*Inputs!$B$23*MIN(1,($A15-Inputs!$B$9+1)/(Inputs!$B$10-Inputs!$B$9+1)))*Inputs!$B$4*$A$5-$B15 -> -4837000 | H15: =H14+IF($A15<Inputs!$B$9,0,B$4*Inputs!$B$23*MIN(1,($A15-Inputs!$B$9+1)/(Inputs!$B$10-Inputs!$B$9+1)))*Inputs!$B$4*$A$6-$B15 -> -4837000 | I15: =I14+IF($A15<Inputs!$B$9,0,C$4*Inputs!$B$23*MIN(1,($A15-Inputs!$B$9+1)/(Inputs!$B$10-Inputs!$B$9+1)))*Inputs!$B$4*$A$6-$B15 -> -4837000 | J15: =J14+IF($A15<Inputs!$B$9,0,D$4*Inputs!$B$23*MIN(1,($A15-Inputs!$B$9+1)/(Inputs!$B$10-Inputs!$B$9+1)))*Inputs!$B$4*$A$6-$B15 -> -4837000 | K15: =K14+IF($A15<Inputs!$B$9,0,E$4*Inputs!$B$23*MIN(1,($A15-Inputs!$B$9+1)/(Inputs!$B$10-Inputs!$B$9+1)))*Inputs!$B$4*$A$6-$B15 -> -4837000 | L15: =L14+IF($A15<Inputs!$B$9,0,F$4*Inputs!$B$23*MIN(1,($A15-Inputs!$B$9+1)/(Inputs!$B$10-Inputs!$B$9+1)))*Inputs!$B$4*$A$6-$B15 -> -4837000 | M15: =M14+IF($A15<Inputs!$B$9,0,B$4*Inputs!$B$23*MIN(1,($A15-Inputs!$B$9+1)/(Inputs!$B$10-Inputs!$B$9+1)))*Inputs!$B$4*$A$7-$B15 -> -4837000 | N15: =N14+IF($A15<Inputs!$B$9,0,C$4*Inputs!$B$23*MIN(1,($A15-Inputs!$B$9+1)/(Inputs!$B$10-Inputs!$B$9+1)))*Inputs!$B$4*$A$7-$B15 -> -4837000 | O15: =O14+IF($A15<Inputs!$B$9,0,D$4*Inputs!$B$23*MIN(1,($A15-Inputs!$B$9+1)/(Inputs!$B$10-Inputs!$B$9+1)))*Inputs!$B$4*$A$7-$B15 -> -4837000 | P15: =P14+IF($A15<Inputs!$B$9,0,E$4*Inputs!$B$23*MIN(1,($A15-Inputs!$B$9+1)/(Inputs!$B$10-Inputs!$B$9+1)))*Inputs!$B$4*$A$7-$B15 -> -4837000 | Q15: =Q14+IF($A15<Inputs!$B$9,0,F$4*Inputs!$B$23*MIN(1,($A15-Inputs!$B$9+1)/(Inputs!$B$10-Inputs!$B$9+1)))*Inputs!$B$4*$A$7-$B15 -> -4837000 | R15: =R14+IF($A15<Inputs!$B$9,0,B$4*Inputs!$B$23*MIN(1,($A15-Inputs!$B$9+1)/(Inputs!$B$10-Inputs!$B$9+1)))*Inputs!$B$4*$A$8-$B15 -> -4837000 | S15: =S14+IF($A15<Inputs!$B$9,0,C$4*Inputs!$B$23*MIN(1,($A15-Inputs!$B$9+1)/(Inputs!$B$10-Inputs!$B$9+1)))*Inputs!$B$4*$A$8-$B15 -> -4837000 | T15: =T14+IF($A15<Inputs!$B$9,0,D$4*Inputs!$B$23*MIN(1,($A15-Inputs!$B$9+1)/(Inputs!$B$10-Inputs!$B$9+1)))*Inputs!$B$4*$A$8-$B15 -> -4837000 | U15: =U14+IF($A15<Inputs!$B$9,0,E$4*Inputs!$B$23*MIN(1,($A15-Inputs!$B$9+1)/(Inputs!$B$10-Inputs!$B$9+1)))*Inputs!$B$4*$A$8-$B15 -> -4837000 | V15: =V14+IF($A15<Inputs!$B$9,0,F$4*Inputs!$B$23*MIN(1,($A15-Inputs!$B$9+1)/(Inputs!$B$10-Inputs!$B$9+1)))*Inputs!$B$4*$A$8-$B15 -> -4837000
A16: 4 | B16: =Cashflow!B8 -> 440333.33 | C16: =C15+IF($A16<Inputs!$B$9,0,B$4*Inputs!$B$23*MIN(1,($A16-Inputs!$B$9+1)/(Inputs!$B$10-Inputs!$B$9+1)))*Inputs!$B$4*$A$5-$B16 -> -5259693.4 | D16: =D15+IF($A16<Inputs!$B$9,0,C$4*Inputs!$B$23*MIN(1,($A16-Inputs!$B$9+1)/(Inputs!$B$10-Inputs!$B$9+1)))*Inputs!$B$4*$A$5-$B16 -> -5253078.5 | E16: =E15+IF($A16<Inputs!$B$9,0,D$4*Inputs!$B$23*MIN(1,($A16-Inputs!$B$9+1)/(Inputs!$B$10-Inputs!$B$9+1)))*Inputs!$B$4*$A$5-$B16 -> -5246463.5 | F16: =F15+IF($A16<Inputs!$B$9,0,E$4*Inputs!$B$23*MIN(1,($A16-Inputs!$B$9+1)/(Inputs!$B$10-Inputs!$B$9+1)))*Inputs!$B$4*$A$5-$B16 -> -5239848.5 | G16: =G15+IF($A16<Inputs!$B$9,0,F$4*Inputs!$B$23*MIN(1,($A16-Inputs!$B$9+1)/(Inputs!$B$10-Inputs!$B$9+1)))*Inputs!$B$4*$A$5-$B16 -> -5233233.6 | H16: =H15+IF($A16<Inputs!$B$9,0,B$4*Inputs!$B$23*MIN(1,($A16-Inputs!$B$9+1)/(Inputs!$B$10-Inputs!$B$9+1)))*Inputs!$B$4*$A$6-$B16 -> -5255283.4 | I16: =I15+IF($A16<Inputs!$B$9,0,C$4*Inputs!$B$23*MIN(1,($A16-Inputs!$B$9+1)/(Inputs!$B$10-Inputs!$B$9+1)))*Inputs!$B$4*$A$6-$B16 -> -5247014.7 | J16: =J15+IF($A16<Inputs!$B$9,0,D$4*Inputs!$B$23*MIN(1,($A16-Inputs!$B$9+1)/(Inputs!$B$10-Inputs!$B$9+1)))*Inputs!$B$4*$A$6-$B16 -> -5238746 | K16: =K15+IF($A16<Inputs!$B$9,0,E$4*Inputs!$B$23*MIN(1,($A16-Inputs!$B$9+1)/(Inputs!$B$10-Inputs!$B$9+1)))*Inputs!$B$4*$A$6-$B16 -> -5230477.3 | L16: =L15+IF($A16<Inputs!$B$9,0,F$4*Inputs!$B$23*MIN(1,($A16-Inputs!$B$9+1)/(Inputs!$B$10-Inputs!$B$9+1)))*Inputs!$B$4*$A$6-$B16 -> -5222208.6 | M16: =M15+IF($A16<Inputs!$B$9,0,B$4*Inputs!$B$23*MIN(1,($A16-Inputs!$B$9+1)/(Inputs!$B$10-Inputs!$B$9+1)))*Inputs!$B$4*$A$7-$B16 -> -5250873.5 | N16: =N15+IF($A16<Inputs!$B$9,0,C$4*Inputs!$B$23*MIN(1,($A16-Inputs!$B$9+1)/(Inputs!$B$10-Inputs!$B$9+1)))*Inputs!$B$4*$A$7-$B16 -> -5240951 | O16: =O15+IF($A16<Inputs!$B$9,0,D$4*Inputs!$B$23*MIN(1,($A16-Inputs!$B$9+1)/(Inputs!$B$10-Inputs!$B$9+1)))*Inputs!$B$4*$A$7-$B16 -> -5231028.6 | P16: =P15+IF($A16<Inputs!$B$9,0,E$4*Inputs!$B$23*MIN(1,($A16-Inputs!$B$9+1)/(Inputs!$B$10-Inputs!$B$9+1)))*Inputs!$B$4*$A$7-$B16 -> -5221106.1 | Q16: =Q15+IF($A16<Inputs!$B$9,0,F$4*Inputs!$B$23*MIN(1,($A16-Inputs!$B$9+1)/(Inputs!$B$10-Inputs!$B$9+1)))*Inputs!$B$4*$A$7-$B16 -> -5211183.7 | R16: =R15+IF($A16<Inputs!$B$9,0,B$4*Inputs!$B$23*MIN(1,($A16-Inputs!$B$9+1)/(Inputs!$B$10-Inputs!$B$9+1)))*Inputs!$B$4*$A$8-$B16 -> -5246463.5 | S16: =S15+IF($A16<Inputs!$B$9,0,C$4*Inputs!$B$23*MIN(1,($A16-Inputs!$B$9+1)/(Inputs!$B$10-Inputs!$B$9+1)))*Inputs!$B$4*$A$8-$B16 -> -5234887.3 | T16: =T15+IF($A16<Inputs!$B$9,0,D$4*Inputs!$B$23*MIN(1,($A16-Inputs!$B$9+1)/(Inputs!$B$10-Inputs!$B$9+1)))*Inputs!$B$4*$A$8-$B16 -> -5223311.1 | U16: =U15+IF($A16<Inputs!$B$9,0,E$4*Inputs!$B$23*MIN(1,($A16-Inputs!$B$9+1)/(Inputs!$B$10-Inputs!$B$9+1)))*Inputs!$B$4*$A$8-$B16 -> -5211734.9 | V16: =V15+IF($A16<Inputs!$B$9,0,F$4*Inputs!$B$23*MIN(1,($A16-Inputs!$B$9+1)/(Inputs!$B$10-Inputs!$B$9+1)))*Inputs!$B$4*$A$8-$B16 -> -5200158.7
A17: 5 | B17: =Cashflow!B9 -> 340333.33 | C17: =C16+IF($A17<Inputs!$B$9,0,B$4*Inputs!$B$23*MIN(1,($A17-Inputs!$B$9+1)/(Inputs!$B$10-Inputs!$B$9+1)))*Inputs!$B$4*$A$5-$B17 -> -5564746.9 | D17: =D16+IF($A17<Inputs!$B$9,0,C$4*Inputs!$B$23*MIN(1,($A17-Inputs!$B$9+1)/(Inputs!$B$10-Inputs!$B$9+1)))*Inputs!$B$4*$A$5-$B17 -> -5544902 | E17: =E16+IF($A17<Inputs!$B$9,0,D$4*Inputs!$B$23*MIN(1,($A17-Inputs!$B$9+1)/(Inputs!$B$10-Inputs!$B$9+1)))*Inputs!$B$4*$A$5-$B17 -> -5525057.1 | F17: =F16+IF($A17<Inputs!$B$9,0,E$4*Inputs!$B$23*MIN(1,($A17-Inputs!$B$9+1)/(Inputs!$B$10-Inputs!$B$9+1)))*Inputs!$B$4*$A$5-$B17 -> -5505212.2 | G17: =G16+IF($A17<Inputs!$B$9,0,F$4*Inputs!$B$23*MIN(1,($A17-Inputs!$B$9+1)/(Inputs!$B$10-Inputs!$B$9+1)))*Inputs!$B$4*$A$5-$B17 -> -5485367.3 | H17: =H16+IF($A17<Inputs!$B$9,0,B$4*Inputs!$B$23*MIN(1,($A17-Inputs!$B$9+1)/(Inputs!$B$10-Inputs!$B$9+1)))*Inputs!$B$4*$A$6-$B17 -> -5551517 | I17: =I16+IF($A17<Inputs!$B$9,0,C$4*Inputs!$B$23*MIN(1,($A17-Inputs!$B$9+1)/(Inputs!$B$10-Inputs!$B$9+1)))*Inputs!$B$4*$A$6-$B17 -> -5526710.9 | J17: =J16+IF($A17<Inputs!$B$9,0,D$4*Inputs!$B$23*MIN(1,($A17-Inputs!$B$9+1)/(Inputs!$B$10-Inputs!$B$9+1)))*Inputs!$B$4*$A$6-$B17 -> -5501904.8 | K17: =K16+IF($A17<Inputs!$B$9,0,E$4*Inputs!$B$23*MIN(1,($A17-Inputs!$B$9+1)/(Inputs!$B$10-Inputs!$B$9+1)))*Inputs!$B$4*$A$6-$B17 -> -5477098.6 | L17: =L16+IF($A17<Inputs!$B$9,0,F$4*Inputs!$B$23*MIN(1,($A17-Inputs!$B$9+1)/(Inputs!$B$10-Inputs!$B$9+1)))*Inputs!$B$4*$A$6-$B17 -> -5452292.5 | M17: =M16+IF($A17<Inputs!$B$9,0,B$4*Inputs!$B$23*MIN(1,($A17-Inputs!$B$9+1)/(Inputs!$B$10-Inputs!$B$9+1)))*Inputs!$B$4*$A$7-$B17 -> -5538287.1 | N17: =N16+IF($A17<Inputs!$B$9,0,C$4*Inputs!$B$23*MIN(1,($A17-Inputs!$B$9+1)/(Inputs!$B$10-Inputs!$B$9+1)))*Inputs!$B$4*$A$7-$B17 -> -5508519.7 | O17: =O16+IF($A17<Inputs!$B$9,0,D$4*Inputs!$B$23*MIN(1,($A17-Inputs!$B$9+1)/(Inputs!$B$10-Inputs!$B$9+1)))*Inputs!$B$4*$A$7-$B17 -> -5478752.4 | P17: =P16+IF($A17<Inputs!$B$9,0,E$4*Inputs!$B$23*MIN(1,($A17-Inputs!$B$9+1)/(Inputs!$B$10-Inputs!$B$9+1)))*Inputs!$B$4*$A$7-$B17 -> -5448985 | Q17: =Q16+IF($A17<Inputs!$B$9,0,F$4*Inputs!$B$23*MIN(1,($A17-Inputs!$B$9+1)/(Inputs!$B$10-Inputs!$B$9+1)))*Inputs!$B$4*$A$7-$B17 -> -5419217.7 | R17: =R16+IF($A17<Inputs!$B$9,0,B$4*Inputs!$B$23*MIN(1,($A17-Inputs!$B$9+1)/(Inputs!$B$10-Inputs!$B$9+1)))*Inputs!$B$4*$A$8-$B17 -> -5525057.1 | S17: =S16+IF($A17<Inputs!$B$9,0,C$4*Inputs!$B$23*MIN(1,($A17-Inputs!$B$9+1)/(Inputs!$B$10-Inputs!$B$9+1)))*Inputs!$B$4*$A$8-$B17 -> -5490328.6 | T17: =T16+IF($A17<Inputs!$B$9,0,D$4*Inputs!$B$23*MIN(1,($A17-Inputs!$B$9+1)/(Inputs!$B$10-Inputs!$B$9+1)))*Inputs!$B$4*$A$8-$B17 -> -5455600 | U17: =U16+IF($A17<Inputs!$B$9,0,E$4*Inputs!$B$23*MIN(1,($A17-Inputs!$B$9+1)/(Inputs!$B$10-Inputs!$B$9+1)))*Inputs!$B$4*$A$8-$B17 -> -5420871.4 | V17: =V16+IF($A17<Inputs!$B$9,0,F$4*Inputs!$B$23*MIN(1,($A17-Inputs!$B$9+1)/(Inputs!$B$10-Inputs!$B$9+1)))*Inputs!$B$4*$A$8-$B17 -> -5386142.9
